Workbook

Sheet Evasion Rate
A1: LA Metro Fare Evasion Dashboard By Alex Davis March 2026
A2: Below is a data-backed estimate of fare evasion on LA Metro, created as part of the Enforce the Fares campaign. Between 2017 and 2020, LA Metro's security department quietly ratcheted down onboard fare checks from around 600,000 a month to just 5,000. Fare evasion skyrocketed, and now, more than half of boardings are unpaid. This policy change cratered fare revenue and worsened safety, but it's not too late to reverse course. To learn more about our campaign to bring back fare checks, visit www.enforcethefares.org.
A5: Route | B5: APC Boardings | C5: Free Day Adjusted Boardings | D5: Paid Entries | E5: Fare Evasion Rate | F5: Notes | G5: Merged Stations (in-gate xfer stations excluded) | H5: APC Boardings | I5: Boardings with Free Day Adjustment | J5: Rail/BRT Station | K5: Paid Entries | L5: Fare Evasion Rate | M5: Notes | N5: Mode | O5: APC Boardings | P5: Paid Boardings | Q5: Fare Evasion Rate | R5: Notes
A6: G Line | B6: =IFERROR( VLOOKUP( A6, 'Bus Ridership'!$A:$B, 2, FALSE ), "" ) -> 4023007 | C6: =B6*'Free Fare Day Adjustment'!$H$3 -> 3709292.2 | D6: ='Station Fare Counts'!K19 -> 723702 | E6: =1-(D6/C6) -> 0.80489485 | F6: The fare total for the G Line is calculated by adding together the Station Fare Counts because on the G Line, fares are paid offboard. | G6: Willowbrook / Rosa Parks Station - A Line | H6: =IFERROR( VLOOKUP( G6, 'Rail Ridership'!$D:$E, 2, FALSE ), "" ) -> 1405270 | I6: =H6*'Free Fare Day Adjustment'!$H$4 -> 1300135.2 | J6: Willowbrook/Rosa Parks (Blue) | K6: =IFERROR( VLOOKUP( J6, 'Station Fare Counts'!$A:$E, 5, FALSE ), "" ) -> 148690 | L6: =1-(K6/I6) -> 0.88563497 | N6: Bus | O6: =Bus_Routes[[#TOTALS],[Free Day Adjusted Boardings]] -> 2.1846644e+08 | P6: =Bus_Routes[[#TOTALS],[Paid Entries]] -> 113034486 | Q6: =1-(P6/O6) -> 0.48260022 | R6: This is the total fare evasion rate for the whole bus system.
A7: 601 | B7: =IFERROR( VLOOKUP( A7, 'Bus Ridership'!$A:$B, 2, FALSE ), "" ) -> 119845 | C7: =B7*'Free Fare Day Adjustment'!$H$3 -> 110499.47 | D7: =IFERROR( VLOOKUP( A7, 'Bus Fare Counts'!$A:$F, 6, FALSE ), "" ) -> 29781 | E7: =1-(D7/C7) -> 0.73048739 | G7: Washington Station | H7: =IFERROR( VLOOKUP( G7, 'Rail Ridership'!$D:$E, 2, FALSE ), "" ) -> 310851 | I7: =H7*'Free Fare Day Adjustment'!$H$4 -> 287594.78 | J7: Washington | K7: =IFERROR( VLOOKUP( J7, 'Station Fare Counts'!$A:$E, 5, FALSE ), "" ) -> 41859 | L7: =1-(K7/I7) -> 0.85445146 | N7: Rail | O7: ='Evasion Rate'!$I$110 -> 50069496 | P7: ='Evasion Rate'!$K$110 -> 21817565 | Q7: =1-(P7/O7) -> 0.56425435 | R7: This is the fare evasion rate for the stations without in-gate transfers.
A8: 154 | B8: =IFERROR( VLOOKUP( A8, 'Bus Ridership'!$A:$B, 2, FALSE ), "" ) -> 214834 | C8: =B8*'Free Fare Day Adjustment'!$H$3 -> 198081.21 | D8: =IFERROR( VLOOKUP( A8, 'Bus Fare Counts'!$A:$F, 6, FALSE ), "" ) -> 61323 | E8: =1-(D8/C8) -> 0.69041485 | G8: 5th Street Station | H8: =IFERROR( VLOOKUP( G8, 'Rail Ridership'!$D:$E, 2, FALSE ), "" ) -> 118497 | I8: =H8*'Free Fare Day Adjustment'!$H$4 -> 109631.68 | J8: 5th Street | K8: =IFERROR( VLOOKUP( J8, 'Station Fare Counts'!$A:$E, 5, FALSE ), "" ) -> 16186 | L8: =1-(K8/I8) -> 0.8523602 | N8: Adjusted Rail | O8: =SUM('Rail Ridership'!$B$2:$B$130) -> 68493991 | P8: =P7*('Rail Ridership'!$B$131/O7) -> 29845959 | Q8: =1-(P8/O8) -> 0.56425435 | R8: When we excluded the in-gate transfer stations, we lowered the total rail ridership in the calculation. So to get the systemwide evasion rate, we have to adjust the rail totals back up to the total for all stations. In other words, we're assuming that on average, the excluded stations had the same evasion rate as the included stations and adjusting the totals as if they were in the calculation. This appropriately weights the relative ridership of Metro's bus and rail systems.
A9: 74 | B9: =IFERROR( VLOOKUP( A9, 'Bus Ridership'!$A:$B, 2, FALSE ), "" ) -> 91659 | C9: =B9*'Free Fare Day Adjustment'!$H$3 -> 84511.416 | D9: =IFERROR( VLOOKUP( A9, 'Bus Fare Counts'!$A:$F, 6, FALSE ), "" ) -> 26928 | E9: =1-(D9/C9) -> 0.68136849 | G9: Downtown Long Beach Station | H9: =IFERROR( VLOOKUP( G9, 'Rail Ridership'!$D:$E, 2, FALSE ), "" ) -> 979428 | I9: =H9*'Free Fare Day Adjustment'!$H$4 -> 906152.41 | J9: Downtown Long Beach | K9: =IFERROR( VLOOKUP( J9, 'Station Fare Counts'!$A:$E, 5, FALSE ), "" ) -> 141659 | L9: =1-(K9/I9) -> 0.84366979 | N9: Total | O9: =SUM(O6,O8) -> 2.8696043e+08 | P9: =SUM(P6,P8) -> 1.4288044e+08 | Q9: =1-(P9/O9) -> 0.50209007 | R9: In 2025, 50% of boardings on LA Metro were unpaid.
A10: 754 | B10: =IFERROR( VLOOKUP( A10, 'Bus Ridership'!$A:$B, 2, FALSE ), "" ) -> 4254701 | C10: =B10*'Free Fare Day Adjustment'!$H$3 -> 3922918.7 | D10: =IFERROR( VLOOKUP( A10, 'Bus Fare Counts'!$A:$F, 6, FALSE ), "" ) -> 1281222 | E10: =1-(D10/C10) -> 0.67340083 | G10: Farmdale Station | H10: =IFERROR( VLOOKUP( G10, 'Rail Ridership'!$D:$E, 2, FALSE ), "" ) -> 285508 | I10: =H10*'Free Fare Day Adjustment'!$H$4 -> 264147.81 | J10: Farmdale | K10: =IFERROR( VLOOKUP( J10, 'Station Fare Counts'!$A:$E, 5, FALSE ), "" ) -> 43935 | L10: =1-(K10/I10) -> 0.83367267 | N10: Attention: This is a roughly half.
A11: 204 | B11: =IFERROR( VLOOKUP( A11, 'Bus Ridership'!$A:$B, 2, FALSE ), "" ) -> 7344834 | C11: =B11*'Free Fare Day Adjustment'!$H$3 -> 6772082.6 | D11: =IFERROR( VLOOKUP( A11, 'Bus Fare Counts'!$A:$F, 6, FALSE ), "" ) -> 2268895 | E11: =1-(D11/C11) -> 0.66496348 | G11: Pico/Aliso Station | H11: =IFERROR( VLOOKUP( G11, 'Rail Ridership'!$D:$E, 2, FALSE ), "" ) -> 241782 | I11: =H11*'Free Fare Day Adjustment'!$H$4 -> 223693.16 | J11: Pico/Aliso | K11: =IFERROR( VLOOKUP( J11, 'Station Fare Counts'!$A:$E, 5, FALSE ), "" ) -> 38106 | L11: =1-(K11/I11) -> 0.82965058
A12: 720 | B12: =IFERROR( VLOOKUP( A12, 'Bus Ridership'!$A:$B, 2, FALSE ), "" ) -> 6233186 | C12: =B12*'Free Fare Day Adjustment'!$H$3 -> 5747121.1 | D12: =IFERROR( VLOOKUP( A12, 'Bus Fare Counts'!$A:$F, 6, FALSE ), "" ) -> 2036312 | E12: =1-(D12/C12) -> 0.64568138 | G12: Slauson Station | H12: =IFERROR( VLOOKUP( G12, 'Rail Ridership'!$D:$E, 2, FALSE ), "" ) -> 420929 | I12: =H12*'Free Fare Day Adjustment'!$H$4 -> 389437.33 | J12: Slauson | K12: =IFERROR( VLOOKUP( J12, 'Station Fare Counts'!$A:$E, 5, FALSE ), "" ) -> 70889 | L12: =1-(K12/I12) -> 0.81797071
A13: 207 | B13: =IFERROR( VLOOKUP( A13, 'Bus Ridership'!$A:$B, 2, FALSE ), "" ) -> 8260287 | C13: =B13*'Free Fare Day Adjustment'!$H$3 -> 7616148.4 | D13: =IFERROR( VLOOKUP( A13, 'Bus Fare Counts'!$A:$F, 6, FALSE ), "" ) -> 2911295 | E13: =1-(D13/C13) -> 0.61774708 | G13: Pacific Coast Hwy Station | H13: =IFERROR( VLOOKUP( G13, 'Rail Ridership'!$D:$E, 2, FALSE ), "" ) -> 536563 | I13: =H13*'Free Fare Day Adjustment'!$H$4 -> 496420.21 | J13: Pacific Coast Highway | K13: =IFERROR( VLOOKUP( J13, 'Station Fare Counts'!$A:$E, 5, FALSE ), "" ) -> 91765 | L13: =1-(K13/I13) -> 0.81514653
A14: J Line | B14: =IFERROR( VLOOKUP( A14, 'Bus Ridership'!$A:$B, 2, FALSE ), "" ) -> 4847233 | C14: =B14*'Free Fare Day Adjustment'!$H$3 -> 4469244.9 | D14: =IFERROR( VLOOKUP( A14, 'Bus Fare Counts'!$A:$F, 6, FALSE ), "" ) -> 1786266 | E14: =1-(D14/C14) -> 0.60032041 | G14: San Pedro Street Station | H14: =IFERROR( VLOOKUP( G14, 'Rail Ridership'!$D:$E, 2, FALSE ), "" ) -> 479903 | I14: =H14*'Free Fare Day Adjustment'!$H$4 -> 443999.21 | J14: San Pedro St | K14: =IFERROR( VLOOKUP( J14, 'Station Fare Counts'!$A:$E, 5, FALSE ), "" ) -> 82208 | L14: =1-(K14/I14) -> 0.81484652
A15: 53 | B15: =IFERROR( VLOOKUP( A15, 'Bus Ridership'!$A:$B, 2, FALSE ), "" ) -> 3635071 | C15: =B15*'Free Fare Day Adjustment'!$H$3 -> 3351607.5 | D15: =IFERROR( VLOOKUP( A15, 'Bus Fare Counts'!$A:$F, 6, FALSE ), "" ) -> 1351789 | E15: =1-(D15/C15) -> 0.59667444 | G15: 1st Street Station | H15: =IFERROR( VLOOKUP( G15, 'Rail Ridership'!$D:$E, 2, FALSE ), "" ) -> 104217 | I15: =H15*'Free Fare Day Adjustment'!$H$4 -> 96420.039 | J15: 1st Street | K15: =IFERROR( VLOOKUP( J15, 'Station Fare Counts'!$A:$E, 5, FALSE ), "" ) -> 18435 | L15: =1-(K15/I15) -> 0.8088053
A16: 4 | B16: =IFERROR( VLOOKUP( A16, 'Bus Ridership'!$A:$B, 2, FALSE ), "" ) -> 7943896 | C16: =B16*'Free Fare Day Adjustment'!$H$3 -> 7324429.6 | D16: =IFERROR( VLOOKUP( A16, 'Bus Fare Counts'!$A:$F, 6, FALSE ), "" ) -> 3202056 | E16: =1-(D16/C16) -> 0.56282521 | G16: Anaheim Street Station | H16: =IFERROR( VLOOKUP( G16, 'Rail Ridership'!$D:$E, 2, FALSE ), "" ) -> 593791 | I16: =H16*'Free Fare Day Adjustment'!$H$4 -> 549366.72 | J16: Anaheim St | K16: =IFERROR( VLOOKUP( J16, 'Station Fare Counts'!$A:$E, 5, FALSE ), "" ) -> 106025 | L16: =1-(K16/I16) -> 0.80700505
A17: 18 | B17: =IFERROR( VLOOKUP( A17, 'Bus Ridership'!$A:$B, 2, FALSE ), "" ) -> 6508534 | C17: =B17*'Free Fare Day Adjustment'!$H$3 -> 6000997.4 | D17: =IFERROR( VLOOKUP( A17, 'Bus Fare Counts'!$A:$F, 6, FALSE ), "" ) -> 2674049 | E17: =1-(D17/C17) -> 0.55439924 | G17: Vermont / Athens Station | H17: =IFERROR( VLOOKUP( G17, 'Rail Ridership'!$D:$E, 2, FALSE ), "" ) -> 476471 | I17: =H17*'Free Fare Day Adjustment'!$H$4 -> 440823.97 | J17: Vermont/Athens | K17: =IFERROR( VLOOKUP( J17, 'Station Fare Counts'!$A:$E, 5, FALSE ), "" ) -> 85598 | L17: =1-(K17/I17) -> 0.80582272
A18: 117 | B18: =IFERROR( VLOOKUP( A18, 'Bus Ridership'!$A:$B, 2, FALSE ), "" ) -> 2753973 | C18: =B18*'Free Fare Day Adjustment'!$H$3 -> 2539217.7 | D18: =IFERROR( VLOOKUP( A18, 'Bus Fare Counts'!$A:$F, 6, FALSE ), "" ) -> 1158460 | E18: =1-(D18/C18) -> 0.54377287 | G18: 103rd Street / Watts Towers Station | H18: =IFERROR( VLOOKUP( G18, 'Rail Ridership'!$D:$E, 2, FALSE ), "" ) -> 602210 | I18: =H18*'Free Fare Day Adjustment'!$H$4 -> 557155.85 | J18: 103rd St/Watts Towers | K18: =IFERROR( VLOOKUP( J18, 'Station Fare Counts'!$A:$E, 5, FALSE ), "" ) -> 111526 | L18: =1-(K18/I18) -> 0.7998298
A19: 51 | B19: =IFERROR( VLOOKUP( A19, 'Bus Ridership'!$A:$B, 2, FALSE ), "" ) -> 5703856 | C19: =B19*'Free Fare Day Adjustment'!$H$3 -> 5259068.3 | D19: =IFERROR( VLOOKUP( A19, 'Bus Fare Counts'!$A:$F, 6, FALSE ), "" ) -> 2438486 | E19: =1-(D19/C19) -> 0.53632738 | G19: Vernon Station | H19: =IFERROR( VLOOKUP( G19, 'Rail Ridership'!$D:$E, 2, FALSE ), "" ) -> 536723 | I19: =H19*'Free Fare Day Adjustment'!$H$4 -> 496568.24 | J19: Vernon | K19: =IFERROR( VLOOKUP( J19, 'Station Fare Counts'!$A:$E, 5, FALSE ), "" ) -> 108456 | L19: =1-(K19/I19) -> 0.78158893
A20: 16 | B20: =IFERROR( VLOOKUP( A20, 'Bus Ridership'!$A:$B, 2, FALSE ), "" ) -> 6406634 | C20: =B20*'Free Fare Day Adjustment'!$H$3 -> 5907043.6 | D20: =IFERROR( VLOOKUP( A20, 'Bus Fare Counts'!$A:$F, 6, FALSE ), "" ) -> 2763128 | E20: =1-(D20/C20) -> 0.53223166 | G20: Expo / Vermont Station | H20: =IFERROR( VLOOKUP( G20, 'Rail Ridership'!$D:$E, 2, FALSE ), "" ) -> 902388 | I20: =H20*'Free Fare Day Adjustment'!$H$4 -> 834876.13 | J20: Expo/Vermont | K20: =IFERROR( VLOOKUP( J20, 'Station Fare Counts'!$A:$E, 5, FALSE ), "" ) -> 182818 | L20: =1-(K20/I20) -> 0.7810238
A21: 45 | B21: =IFERROR( VLOOKUP( A21, 'Bus Ridership'!$A:$B, 2, FALSE ), "" ) -> 4179859 | C21: =B21*'Free Fare Day Adjustment'!$H$3 -> 3853912.9 | D21: =IFERROR( VLOOKUP( A21, 'Bus Fare Counts'!$A:$F, 6, FALSE ), "" ) -> 1807093 | E21: =1-(D21/C21) -> 0.53110175 | G21: Redondo Beach Station | H21: =IFERROR( VLOOKUP( G21, 'Rail Ridership'!$D:$E, 2, FALSE ), "" ) -> 265660 | I21: =H21*'Free Fare Day Adjustment'!$H$4 -> 245784.73 | J21: Redondo Beach | K21: =IFERROR( VLOOKUP( J21, 'Station Fare Counts'!$A:$E, 5, FALSE ), "" ) -> 54059 | L21: =1-(K21/I21) -> 0.7800555
A22: 115 | B22: =IFERROR( VLOOKUP( A22, 'Bus Ridership'!$A:$B, 2, FALSE ), "" ) -> 3745786 | C22: =B22*'Free Fare Day Adjustment'!$H$3 -> 3453689 | D22: =IFERROR( VLOOKUP( A22, 'Bus Fare Counts'!$A:$F, 6, FALSE ), "" ) -> 1639626 | E22: =1-(D22/C22) -> 0.52525372 | G22: Grand / LATTC Station | H22: =IFERROR( VLOOKUP( G22, 'Rail Ridership'!$D:$E, 2, FALSE ), "" ) -> 678510 | I22: =H22*'Free Fare Day Adjustment'!$H$4 -> 627747.49 | J22: Grand/LATTC | K22: =IFERROR( VLOOKUP( J22, 'Station Fare Counts'!$A:$E, 5, FALSE ), "" ) -> 139080 | L22: =1-(K22/I22) -> 0.77844595
A23: 20 | B23: =IFERROR( VLOOKUP( A23, 'Bus Ridership'!$A:$B, 2, FALSE ), "" ) -> 2862204 | C23: =B23*'Free Fare Day Adjustment'!$H$3 -> 2639008.8 | D23: =IFERROR( VLOOKUP( A23, 'Bus Fare Counts'!$A:$F, 6, FALSE ), "" ) -> 1258141 | E23: =1-(D23/C23) -> 0.52325245 | G23: Hawthorne / Lennox Station | H23: =IFERROR( VLOOKUP( G23, 'Rail Ridership'!$D:$E, 2, FALSE ), "" ) -> 437613 | I23: =H23*'Free Fare Day Adjustment'!$H$4 -> 404873.12 | J23: Hawthorne/Lennox | K23: =IFERROR( VLOOKUP( J23, 'Station Fare Counts'!$A:$E, 5, FALSE ), "" ) -> 94852 | L23: =1-(K23/I23) -> 0.76572414
A24: 210 | B24: =IFERROR( VLOOKUP( A24, 'Bus Ridership'!$A:$B, 2, FALSE ), "" ) -> 4352659 | C24: =B24*'Free Fare Day Adjustment'!$H$3 -> 4013237.9 | D24: =IFERROR( VLOOKUP( A24, 'Bus Fare Counts'!$A:$F, 6, FALSE ), "" ) -> 1918442 | E24: =1-(D24/C24) -> 0.52197152 | G24: 17th Street / SMC Station | H24: =IFERROR( VLOOKUP( G24, 'Rail Ridership'!$D:$E, 2, FALSE ), "" ) -> 502057 | I24: =H24*'Free Fare Day Adjustment'!$H$4 -> 464495.77 | J24: 17th St/SMC | K24: =IFERROR( VLOOKUP( J24, 'Station Fare Counts'!$A:$E, 5, FALSE ), "" ) -> 109532 | L24: =1-(K24/I24) -> 0.76419161
A25: 66 | B25: =IFERROR( VLOOKUP( A25, 'Bus Ridership'!$A:$B, 2, FALSE ), "" ) -> 4002195 | C25: =B25*'Free Fare Day Adjustment'!$H$3 -> 3690103.2 | D25: =IFERROR( VLOOKUP( A25, 'Bus Fare Counts'!$A:$F, 6, FALSE ), "" ) -> 1783296 | E25: =1-(D25/C25) -> 0.51673546 | G25: Expo / Western Station | H25: =IFERROR( VLOOKUP( G25, 'Rail Ridership'!$D:$E, 2, FALSE ), "" ) -> 879577 | I25: =H25*'Free Fare Day Adjustment'!$H$4 -> 813771.73 | J25: Expo/Western | K25: =IFERROR( VLOOKUP( J25, 'Station Fare Counts'!$A:$E, 5, FALSE ), "" ) -> 202397 | L25: =1-(K25/I25) -> 0.75128529
A26: 40 | B26: =IFERROR( VLOOKUP( A26, 'Bus Ridership'!$A:$B, 2, FALSE ), "" ) -> 4328513 | C26: =B26*'Free Fare Day Adjustment'!$H$3 -> 3990974.8 | D26: =IFERROR( VLOOKUP( A26, 'Bus Fare Counts'!$A:$F, 6, FALSE ), "" ) -> 1936273 | E26: =1-(D26/C26) -> 0.51483708 | G26: Artesia Station | H26: =IFERROR( VLOOKUP( G26, 'Rail Ridership'!$D:$E, 2, FALSE ), "" ) -> 508580 | I26: =H26*'Free Fare Day Adjustment'!$H$4 -> 470530.75 | J26: Artesia | K26: =IFERROR( VLOOKUP( J26, 'Station Fare Counts'!$A:$E, 5, FALSE ), "" ) -> 117145 | L26: =1-(K26/I26) -> 0.75103646
... A108: 76 | B108: =IFERROR( VLOOKUP( A108, 'Bus Ridership'!$A:$B, 2, FALSE ), "" ) -> 2021710 | C108: =B108*'Free Fare Day Adjustment'!$H$3 -> 1864056.7 | D108: =IFERROR( VLOOKUP( A108, 'Bus Fare Counts'!$A:$F, 6, FALSE ), "" ) -> 1346676 | E108: =1-(D108/C108) -> 0.27755631 | G108: Union Station - Metro Red & Purple Lines | H108: =IFERROR( VLOOKUP( G108, 'Rail Ridership'!$D:$E, 2, FALSE ), "" ) -> 1928865 | I108: =H108*'Free Fare Day Adjustment'!$H$4 -> 1784557.6 | J108: Union Station (Red) | K108: =IFERROR( VLOOKUP( J108, 'Station Fare Counts'!$A:$E, 5, FALSE ), "" ) -> 1634919 | L108: =1-(K108/I108) -> 0.083851922
A109: 179 | B109: =IFERROR( VLOOKUP( A109, 'Bus Ridership'!$A:$B, 2, FALSE ), "" ) -> 308674 | C109: =B109*'Free Fare Day Adjustment'!$H$3 -> 284603.55 | D109: =IFERROR( VLOOKUP( A109, 'Bus Fare Counts'!$A:$F, 6, FALSE ), "" ) -> 206550 | E109: =1-(D109/C109) -> 0.2742536 | G109: North Hollywood Station | H109: =IFERROR( VLOOKUP( G109, 'Rail Ridership'!$D:$E, 2, FALSE ), "" ) -> 2126497 | I109: =H109*'Free Fare Day Adjustment'!$H$4 -> 1967403.8 | J109: North Hollywood (Red) | K109: =IFERROR( VLOOKUP( J109, 'Station Fare Counts'!$A:$E, 5, FALSE ), "" ) -> 2195180 | L109: =1-(K109/I109) -> -0.11577501 | M109: This is likely a result of TAP-to-Exit. In 2025, the TAP-to-Exit pilot caused many B Line fare evaders to end up getting charged at North Hollywood when exiting, resulting in more fares than boardings. To be clear, I freely concede that TAP-to-Exit works at individual stations. My point is that it only works when TSOs are present and that's what's causing the fare compliance, not the tapping proceedure. And we'll never have enough TSOs to babysit even half the system's faregates. TAP-to-Exit is a performative distraction from the real solution: fare checks.
A110: 662 | B110: =IFERROR( VLOOKUP( A110, 'Bus Ridership'!$A:$B, 2, FALSE ), "" ) -> 461287 | C110: =B110*'Free Fare Day Adjustment'!$H$3 -> 425315.76 | D110: =IFERROR( VLOOKUP( A110, 'Bus Fare Counts'!$A:$F, 6, FALSE ), "" ) -> 310979 | E110: =1-(D110/C110) -> 0.26882794 | G110: Total | H110: =SUM(Rail_Stations[APC Boardings]) -> 54118342 | I110: =SUM(Rail_Stations[Boardings with Free Day Adjustment]) -> 50069496 | J110: Total | K110: =SUM(Rail_Stations[Paid Entries]) -> 21817565 | L110: =1-(K110/I110) -> 0.56425435
A111: 287 | B111: =IFERROR( VLOOKUP( A111, 'Bus Ridership'!$A:$B, 2, FALSE ), "" ) -> 273866 | C111: =B111*'Free Fare Day Adjustment'!$H$3 -> 252509.88 | D111: =IFERROR( VLOOKUP( A111, 'Bus Fare Counts'!$A:$F, 6, FALSE ), "" ) -> 188401 | E111: =1-(D111/C111) -> 0.25388663
A112: 268 | B112: =IFERROR( VLOOKUP( A112, 'Bus Ridership'!$A:$B, 2, FALSE ), "" ) -> 233229 | C112: =B112*'Free Fare Day Adjustment'!$H$3 -> 215041.76 | D112: =IFERROR( VLOOKUP( A112, 'Bus Fare Counts'!$A:$F, 6, FALSE ), "" ) -> 169937 | E112: =1-(D112/C112) -> 0.20974885
A113: 267 | B113: =IFERROR( VLOOKUP( A113, 'Bus Ridership'!$A:$B, 2, FALSE ), "" ) -> 552877 | C113: =B113*'Free Fare Day Adjustment'!$H$3 -> 509763.56 | D113: =IFERROR( VLOOKUP( A113, 'Bus Fare Counts'!$A:$F, 6, FALSE ), "" ) -> 409443 | E113: =1-(D113/C113) -> 0.19679821
A114: 155 | B114: =IFERROR( VLOOKUP( A114, 'Bus Ridership'!$A:$B, 2, FALSE ), "" ) -> 410023 | C114: =B114*'Free Fare Day Adjustment'!$H$3 -> 378049.34 | D114: =IFERROR( VLOOKUP( A114, 'Bus Fare Counts'!$A:$F, 6, FALSE ), "" ) -> 318569 | E114: =1-(D114/C114) -> 0.15733485
A115: 501 | B115: =IFERROR( VLOOKUP( A115, 'Bus Ridership'!$A:$B, 2, FALSE ), "" ) -> 434223 | C115: =B115*'Free Fare Day Adjustment'!$H$3 -> 400362.22 | D115: =IFERROR( VLOOKUP( A115, 'Bus Fare Counts'!$A:$F, 6, FALSE ), "" ) -> 351203 | E115: =1-(D115/C115) -> 0.12278685
A116: 857 | B116: =IFERROR( VLOOKUP( A116, 'Bus Ridership'!$A:$B, 2, FALSE ), "" ) -> 146352 | C116: =B116*'Free Fare Day Adjustment'!$H$3 -> 134939.45 | D116: N/A | E116: N/A | F116: This was the bus Metro operated to link the two K Line fragments before the line was completed in June 2025. While its ridership was properly tabulated, its fare data got dumped into the "unclassified" row.
A117: Misclassified | B117: N/A | D117: 152766 | E117: N/A | F117: These fares were accidentally attributed to bus routes that were not operating in 2025. They are data errors and represent about 0.14% of the total fares paid. But we are including them anyway because they were likely real fares paid on other routes.
A118: Unclassified | B118: N/A | D118: =IFERROR( VLOOKUP( A118, 'Bus Fare Counts'!$A:$F, 6, FALSE ), "" ) -> 41340 | E118: N/A | F118: These are also real fares that were paid. We just don't know where because they weren't attributed to any specific route. We believe these are primarily from temporary routes like the 857.
A119: Total | B119: =SUM(B5:B118) -> 236943315 | C119: =SUM(C5:C118) -> 2.1846644e+08 | D119: =SUM(D5:D118) -> 113034486 | E119: =1-(D119/C119) -> 0.48260022

Sheet Methodology
A1: How I Calculated LA Metro's 2025 Fare Evasion Rate This is an explanation of how I (Alex Davis) calculated LA Metro's fare evasion rate by comparing route and station-level fare data against ridership totals. I did this in March 2026 as part of the Enforce the Fares campaign. To learn more, visit www.enforcethefares.org. Below, I've provided the full end-to-end methodology so you can check my work. If you spot any error or oversight in my methodology, please reach out to ametroworthpayingfor@gmail.com. This process started with five sources of data: 1. 2025 bus route ridership from LA Metro's ridership data portal. (https://opa.metro.net/MetroRidership/) You can view this data in the Bus Ridership sheet. This data was collected by the automated passenger counters (APCs) above the doors on buses, so it includes everyone who boards the bus, even those who don't pay. 2. 2025 bus fare totals. (Records request) You can view the original, unmodified records request response data in the Bus Fare Counts sheet. This is a measure of the total authorized entries to the bus routes. It's created by adding together the TAP fares, cash fares, discount pass taps (GoPass, LIFE, etc) and TAP transfers. This is then compared against the total APC boardings to reveal the fare evasion rate. 3. 2025 rail and G Line station fare totals. (Records request) You can view the original, unmodified* request response in the Rail Fare Counts sheet. (*Metro included the G Line stations in this table along with a random bus loop. I have sorted those into their own sections for improved legibility.) This is also a measure of total authorized entries to rail stations. On the rail system, fares are paid at the station, not on the train. So at stations with multiple train lines, we typically only have the total for all trains. That means we have to calculate rail fare evasion by station, not line. The G Line is also included in this table, since its fares are also collected offboard. 4. 2025 rail station ridership totals. (Records request) These totals were extrapolated from month-by-month daily averages, which you can see an example of in the "Rail Ridership Raw Data Example" sheet. This data was collected by the APCs onboard trains, so it includes everyone who boards the train, even those who don't pay. 6. 2025 fare free days. (Social media) I just googled and asked around to figure out how many official free fare days there were in 2025. The sources are listed in the Free Fare Day Adjustment Bus Methodology Buses are simple. I calculated the bus fare evasion rate by subtracting the total fare count from the ridership for each line. For the G Line, I added up all the fare payments across all of the G Line's stations. There were some anomalies (like bus fares attributed to routes no longer operating), but these represented less than 0.2% of total ridership. Rail Methodology Rail was more complicated. Metro's Records Management Center was unable to give me the total APC boardings for every rail station in 2025. Instead, the data was stored in 12 separate files (one for each month). And instead of totals, the ridership was averages for weekdays, Saturdays and Sundays. To get the totals, I multiplied these numbers by the number of that day type there were in that month. You can see an example of this process in the "Rail Ridership Raw Data Example" sheet. You can see the outputs for each month on the right side of the Rail Ridership sheet. (Notice, not all the months have the same number of stations. This is because of the LAX and Pomona extension openings.) I then added up the ridership in all 12 months for every station. Then I cleaned the data by combining station codes that represented different lines in the same station and any other case where multiple codes referred to the same station. I also removed 7th/Metro Center, Aviation/Century, LAX, Pico, Wilshire/Vermont and Little Tokyo. That's because these stations allow riders to transfer inside of the faregates, which would create an APC boarding but not a TAP transfer. Since these boardings would be indistinguishable from fare evasion, I've excluded these stations from the calculation. In the evasion rate table, you'll notice that the ridership data and fare data use different formats for the station names. I matched these up manually and am showing the original names for methodological transparency. Free Fare Days In 2025, LA Metro officially suspended fare collection on 29 days. 5 were to celebrate rail extension openings, 6 were on holidays and 18 were during the January 2025 LA wildfire emergency, when the Board suspended fare collection for two weeks as an emergency measure. People boarding without paying on these days aren't evading, so to calculate fare evasion rates, we need to exclude these boardings from the totals. To estimate the number of free day boardings, I assumbed that each day has the same number boardings as its day type average in its month. I then added up the 2025 total and divided it by the ridership for the whole year (one for bus and one for rail). This created the Free Day Adjustment Factor, which I multiplied by the APC boardings for routes and stations. Putting it All Together There's one more step. To get the systemwide fare evasion rate, we just add together the free day adjusted rail boardings and bus boardings, and compare them against the rail fares and bus fares. The problem is that when we excluded the six in-gate transfer stations, we reduced the rail totals. So to keep the bus-rail ratio accurate, we bring back the original total ridership and increase the fare count by that same percentage. In other words, we are assuming that the excluded stations had on average the same evasion rate as the others. This result, added with the bus totals, gives us the final fare evasion rate for the entire system.
K2: 7th/Metro Center, Aviation/Century, LAX, Pico, Wilshire/Vermont, Little Tokyo

Sheet Free Fare Day Adjustment
A2: Free days in 2025 | B2: Estimated Bus Ridership | C2: Estimated Rail Ridership | D2: Reference | E2: Reason | G2: Free Day Adjustment Factors
A3: 45666 | B3: 729709 | C3: 188666 | D3: Jan Wkdy | E3: Emergency Suspension for LA Fires | G3: Bus | H3: =1-(Free_Fare_Days[[#TOTALS],[Estimated Bus Ridership]]/'Bus Ridership'!B114) -> 0.92201983
A4: 45667 | B4: 729709 | C4: 188666 | D4: Jan Wkdy | E4: Emergency Suspension for LA Fires | G4: Rail | H4: =1-(Free_Fare_Days[[#TOTALS],[Estimated Rail Ridership]]/'Rail Ridership'!B131) -> 0.92518532
A5: 45668 | B5: 502735 | C5: 143662 | D5: Jan Sat | E5: Emergency Suspension for LA Fires
A6: 45669 | B6: 395323 | C6: 118382 | D6: Jan Sun | E6: Emergency Suspension for LA Fires
A7: 45670 | B7: 729709 | C7: 188666 | D7: Jan Wkdy | E7: Emergency Suspension for LA Fires
A8: 45671 | B8: 729709 | C8: 188666 | D8: Jan Wkdy | E8: Emergency Suspension for LA Fires
A9: 45672 | B9: 729709 | C9: 188666 | D9: Jan Wkdy | E9: Emergency Suspension for LA Fires | G9: Sources:
A10: 45673 | B10: 729709 | C10: 188666 | D10: Jan Wkdy | E10: Emergency Suspension for LA Fires | G10: https://www.instagram.com/p/DFgp3ejSsfY/?igsh=NTc4MTIwNjQ2YQ==
A11: 45674 | B11: 729709 | C11: 188666 | D11: Jan Wkdy | E11: Emergency Suspension for LA Fires | G11: https://www.dailynews.com/2025/01/25/after-wildfire-pause-la-metro-will-start-collecting-fares-again-on-monday/
A12: 45675 | B12: 502735 | C12: 143662 | D12: Jan Sat | E12: Emergency Suspension for LA Fires | G12: https://laist.com/news/transportation/la-metro-lax-airport-people-mover
A13: 45676 | B13: 395323 | C13: 118382 | D13: Jan Sun | E13: Emergency Suspension for LA Fires | G13: https://thesource.metro.net/how-to-ride-the-a-line-extension-to-glendora-san-dimas-la-verne-fairplex-and-pomona-north/
A14: 45677 | B14: 729709 | C14: 188666 | D14: Jan Wkdy | E14: Emergency Suspension for LA Fires
A15: 45678 | B15: 729709 | C15: 188666 | D15: Jan Wkdy | E15: Emergency Suspension for LA Fires
A16: 45679 | B16: 729709 | C16: 188666 | D16: Jan Wkdy | E16: Emergency Suspension for LA Fires
A17: 45680 | B17: 729709 | C17: 188666 | D17: Jan Wkdy | E17: Emergency Suspension for LA Fires
A18: 45681 | B18: 729709 | C18: 188666 | D18: Jan Wkdy | E18: Emergency Suspension for LA Fires
A19: 45682 | B19: 502735 | C19: 143662 | D19: Jan Sat | E19: Emergency Suspension for LA Fires
A20: 45683 | B20: 395323 | C20: 118382 | D20: Jan Sun | E20: Emergency Suspension for LA Fires
A21: 45692 | B21: 739337 | C21: 206434 | D21: Feb Wkdy | E21: Transit Equity Day
A22: 45769 | B22: 766058 | C22: 212682 | D22: Apr Wkdy | E22: Earth Day
A23: 45792 | B23: 791214 | C23: 212272 | D23: May Wkdy | E23: Bike to Work Day
A24: 45931 | B24: 760709 | C24: 216796 | D24: Oct Wkdy | E24: CA Clean Air Day
A25: 46015 | B25: 692420 | C25: 201308 | D25: Dec Wkdy | E25: Christmas Eve
... A31: 45921 | B31: 437404 | C31: 149077 | D31: Sep Sun | E31: Pomona North Opening Weekend
A32: Total | B32: =SUM(Free_Fare_Days[Estimated Bus Ridership]) -> 18476885 | C32: =SUM(Free_Fare_Days[Estimated Rail Ridership]) -> 5124356

Sheet Bus Ridership
A1: Line | B1: Ridership
A2: 2 | B2: 6166572
A3: 4 | B3: 7943896
A4: 10 | B4: 2236005
A5: 14 | B5: 3766391
A6: 16 | B6: 6406634
A7: 18 | B7: 6508534
A8: 20 | B8: 2862204
A9: 28 | B9: 3331543
A10: 30 | B10: 2660591
A11: 33 | B11: 5437771
A12: 35 | B12: 1607672
A13: 40 | B13: 4328513
... A111: 857 | B111: 146352
A112: G Line | B112: 4023007
A113: J Line | B113: 4847233
A114: Total | B114: =SUM(B2:B113) -> 236943381

Sheet Bus Fare Counts
A1: Bus Route | B1: Cash | C1: TAP Discount Fares | D1: TAP Fares | E1: TAP Transfers | F1: Total Paid Boardings
A2: 10 | B2: 455519 | C2: 254473 | D2: 319863 | E2: 129234 | F2: =SUM(B2:E2) -> 1159089
A3: 102 | B3: 110757 | C3: 55289 | D3: 76210 | E3: 31209 | F3: =SUM(B3:E3) -> 273465
A4: 105 | B4: 907452 | C4: 376325 | D4: 502902 | E4: 293477 | F4: =SUM(B4:E4) -> 2080156
A5: 106 | B5: 238786 | C5: 152109 | D5: 220441 | E5: 90026 | F5: =SUM(B5:E5) -> 701362
A6: 108 | B6: 1069867 | C6: 383212 | D6: 465626 | E6: 304072 | F6: =SUM(B6:E6) -> 2222777
A7: 110 | B7: 597076 | C7: 233593 | D7: 248697 | E7: 122808 | F7: =SUM(B7:E7) -> 1202174
A8: 111 | B8: 1118148 | C8: 319742 | D8: 445839 | E8: 257570 | F8: =SUM(B8:E8) -> 2141299
A9: 115 | B9: 769453 | C9: 270453 | D9: 373543 | E9: 226177 | F9: =SUM(B9:E9) -> 1639626
A10: 117 | B10: 556497 | C10: 196003 | D10: 286589 | E10: 119371 | F10: =SUM(B10:E10) -> 1158460
A11: 120 | B11: 244965 | C11: 82233 | D11: 137910 | E11: 60938 | F11: =SUM(B11:E11) -> 526046
A12: 125 | B12: 419683 | C12: 120089 | D12: 182102 | E12: 88350 | F12: =SUM(B12:E12) -> 810224
A13: 126 | B13: 143 | C13: 48 | D13: 64 | E13: 31 | F13: =SUM(B13:E13) -> 286
... A33: 17 | B33: 154 | C33: 31 | D33: 85 | E33: 50 | F33: =SUM(B33:E33) -> 320
A34: 177 | D34: 1 | F34: =SUM(B34:E34) -> 1
A35: 179 | B35: 67149 | C35: 23502 | D35: 78686 | E35: 37213 | F35: =SUM(B35:E35) -> 206550
A36: 18 | B36: 1175645 | C36: 529763 | D36: 638996 | E36: 329645 | F36: =SUM(B36:E36) -> 2674049
A37: 180 | B37: 544363 | C37: 210509 | D37: 563213 | E37: 237203 | F37: =SUM(B37:E37) -> 1555288
A38: 181 | B38: 49 | C38: 32 | D38: 55 | E38: 20 | F38: =SUM(B38:E38) -> 156
A39: 182 | B39: 203776 | C39: 101514 | D39: 164457 | E39: 57488 | F39: =SUM(B39:E39) -> 527235
A40: 194 | B40: 12 | C40: 4 | D40: 14 | F40: =SUM(B40:E40) -> 30
A41: 2 | B41: 1162112 | C41: 561204 | D41: 983836 | E41: 434909 | F41: =SUM(B41:E41) -> 3142061
A42: 20 | B42: 440787 | C42: 218812 | D42: 415336 | E42: 183206 | F42: =SUM(B42:E42) -> 1258141
A43: 200 | B43: 36 | C43: 14 | D43: 27 | E43: 11 | F43: =SUM(B43:E43) -> 88
A44: 201 | B44: 43 | C44: 21 | D44: 35 | E44: 13 | F44: =SUM(B44:E44) -> 112
A45: 202 | B45: 12316 | C45: 6869 | D45: 9970 | E45: 5125 | F45: =SUM(B45:E45) -> 34280
A46: 204 | B46: 903129 | C46: 466249 | D46: 579069 | E46: 320448 | F46: =SUM(B46:E46) -> 2268895
A47: 205 | B47: 232504 | C47: 88303 | D47: 128100 | E47: 62240 | F47: =SUM(B47:E47) -> 511147
A48: 206 | B48: 626618 | C48: 286936 | D48: 363725 | E48: 171624 | F48: =SUM(B48:E48) -> 1448903
A49: 207 | B49: 1153841 | C49: 548285 | D49: 768478 | E49: 440691 | F49: =SUM(B49:E49) -> 2911295
A50: 209 | B50: 16715 | C50: 8768 | D50: 14362 | E50: 6581 | F50: =SUM(B50:E50) -> 46426
A51: 210 | B51: 737422 | C51: 321966 | D51: 548431 | E51: 310623 | F51: =SUM(B51:E51) -> 1918442
A52: 211 | B52: 19560 | C52: 8424 | D52: 10391 | E52: 4285 | F52: =SUM(B52:E52) -> 42660
... A145: 78 | B145: 484841 | C145: 212169 | D145: 483307 | E145: 211116 | F145: =SUM(B145:E145) -> 1391433
A146: 780 | B146: 1 | F146: =SUM(B146:E146) -> 1
A147: 788 | B147: 209 | C147: 85 | D147: 227 | E147: 94 | F147: =SUM(B147:E147) -> 615
A148: 79 | B148: 114 | C148: 22 | D148: 77 | E148: 29 | F148: =SUM(B148:E148) -> 242
A149: 81 | B149: 663761 | C149: 275004 | D149: 404003 | E149: 180361 | F149: =SUM(B149:E149) -> 1523129
A150: 83 | B150: 44 | C150: 24 | D150: 18 | E150: 14 | F150: =SUM(B150:E150) -> 100
A151: 90 | B151: 557095 | C151: 208443 | D151: 325644 | E151: 153892 | F151: =SUM(B151:E151) -> 1245074
...

Sheet Station Fare Counts
A1: Rail Station | B1: TAP Discount Fares | C1: TAP Fares | D1: TAP Transfer | E1: Total Paid Entries | G1: G Line Station | H1: TAP Discount Fares | I1: TAP Fares | J1: TAP Transfer | K1: Total Paid Entries | M1: Anomaly | N1: TAP Discount Fares | O1: TAP Fares | P1: TAP Transfer | Q1: Total Paid Entries
A2: 103rd St/Watts Towers | B2: 30985 | C2: 62736 | D2: 17805 | E2: =SUM(B2:D2) -> 111526 | G2: Balboa | H2: 7552 | I2: 18896 | J2: 6352 | K2: =SUM(H2:J2) -> 32800 | M2: CSUN Transit Center | N2: 109 | O2: 180 | P2: 19 | Q2: =SUM(N2:P2) -> 308
A3: 17th St/SMC | B3: 33445 | C3: 70903 | D3: 5184 | E3: =SUM(B3:D3) -> 109532 | G3: Canoga | H3: 4832 | I3: 19815 | J3: 7615 | K3: =SUM(H3:J3) -> 32262 | M3: Note: Cal State Northridge doesn't have offboard fare collection, but Metro included this anyway. Your guess as to why is as good as mine.
A4: 1st Street | B4: 3437 | C4: 14219 | D4: 779 | E4: =SUM(B4:D4) -> 18435 | G4: Chatsworth | H4: 4844 | I4: 12536 | J4: 1789 | K4: =SUM(H4:J4) -> 19169
A5: 26th St/Bergamot | B5: 19978 | C5: 89616 | D5: 4251 | E5: =SUM(B5:D5) -> 113845 | G5: De Soto | H5: 4490 | I5: 12520 | J5: 3896 | K5: =SUM(H5:J5) -> 20906
A6: 5th Street | B6: 4622 | C6: 10509 | D6: 1055 | E6: =SUM(B6:D6) -> 16186 | G6: Laurel Canyon | H6: 10394 | I6: 27420 | J6: 4564 | K6: =SUM(H6:J6) -> 42378
A7: 7th St/Metro Center (Blue) | B7: 185256 | C7: 725229 | D7: 471919 | E7: =SUM(B7:D7) -> 1382404 | G7: Nordhoff | H7: 2859 | I7: 9321 | J7: 3601 | K7: =SUM(H7:J7) -> 15781
A8: 7th St/Metro Center (Red) | B8: 146128 | C8: 715242 | D8: 436991 | E8: =SUM(B8:D8) -> 1298361 | G8: North Hollywood (Orange) | H8: 30746 | I8: 56014 | J8: 153058 | K8: =SUM(H8:J8) -> 239818
A9: Allen | B9: 16732 | C9: 94960 | D9: 10766 | E9: =SUM(B9:D9) -> 122458 | G9: Pierce College | H9: 14985 | I9: 14133 | J9: 2249 | K9: =SUM(H9:J9) -> 31367
A10: Anaheim St | B10: 30487 | C10: 62457 | D10: 13081 | E10: =SUM(B10:D10) -> 106025 | G10: Reseda | H10: 13600 | I10: 38498 | J10: 14018 | K10: =SUM(H10:J10) -> 66116
A11: APU/Citrus College | B11: 20115 | C11: 101527 | D11: 4611 | E11: =SUM(B11:D11) -> 126253 | G11: Roscoe | H11: 6295 | I11: 16602 | J11: 3018 | K11: =SUM(H11:J11) -> 25915
A12: Arcadia | B12: 15189 | C12: 94541 | D12: 12827 | E12: =SUM(B12:D12) -> 122557 | G12: Sepulveda | H12: 11520 | I12: 24846 | J12: 15245 | K12: =SUM(H12:J12) -> 51611
A13: Artesia | B13: 30340 | C13: 57685 | D13: 29120 | E13: =SUM(B13:D13) -> 117145 | G13: Sherman Way | H13: 8874 | I13: 24966 | J13: 3382 | K13: =SUM(H13:J13) -> 37222
A14: Atlantic | B14: 35496 | C14: 108342 | D14: 28110 | E14: =SUM(B14:D14) -> 171948 | G14: Tampa | H14: 3991 | I14: 10090 | J14: 2390 | K14: =SUM(H14:J14) -> 16471
A15: Avalon | B15: 27568 | C15: 39399 | D15: 20433 | E15: =SUM(B15:D15) -> 87400 | G15: Valley College | H15: 17065 | I15: 14892 | J15: 1592 | K15: =SUM(H15:J15) -> 33549
... A18: Azusa Downtown | B18: 18655 | C18: 75860 | D18: 14846 | E18: =SUM(B18:D18) -> 109361 | G18: Woodman | H18: 6477 | I18: 18322 | J18: 3231 | K18: =SUM(H18:J18) -> 28030
A19: Chinatown | B19: 17215 | C19: 93272 | D19: 13177 | E19: =SUM(B19:D19) -> 123664 | G19: G Line Total | H19: =SUM(H1:H18) -> 155860 | I19: =SUM(I1:I18) -> 337387 | J19: =SUM(J1:J18) -> 230455 | K19: =SUM(H19:J19) -> 723702
A20: Civic Center/Grand Park | B20: 42734 | C20: 202968 | D20: 57823 | E20: =SUM(B20:D20) -> 303525
A21: Compton | B21: 33340 | C21: 92161 | D21: 27560 | E21: =SUM(B21:D21) -> 153061
A22: Crenshaw | B22: 18558 | C22: 57028 | D22: 26325 | E22: =SUM(B22:D22) -> 101911
A23: Culver City | B23: 54895 | C23: 187795 | D23: 53268 | E23: =SUM(B23:D23) -> 295958
A24: Del Amo | B24: 35458 | C24: 79300 | D24: 22026 | E24: =SUM(B24:D24) -> 136784
A25: Del Mar | B25: 14298 | C25: 100592 | D25: 19062 | E25: =SUM(B25:D25) -> 133952
A26: Douglas | B26: 5133 | C26: 25398 | D26: 6025 | E26: =SUM(B26:D26) -> 36556
A27: Downtown Inglewood | B27: 11544 | C27: 35234 | D27: 13978 | E27: =SUM(B27:D27) -> 60756
A28: Downtown Long Beach | B28: 34131 | C28: 92861 | D28: 14667 | E28: =SUM(B28:D28) -> 141659
A29: Downtown Santa Monica | B29: 237242 | C29: 704382 | D29: 458972 | E29: =SUM(B29:D29) -> 1400596
A30: Duarte/City of Hope | B30: 13739 | C30: 50839 | D30: 2269 | E30: =SUM(B30:D30) -> 66847
A31: E LA Civic Center | B31: 12208 | C31: 24642 | D31: 6509 | E31: =SUM(B31:D31) -> 43359
... A112: Wilshire/Western | B112: 39744 | C112: 160025 | D112: 51747 | E112: =SUM(B112:D112) -> 251516
A113: Rail Total | B113: =SUM(B2:B112) -> 4218880 | C113: =SUM(C2:C112) -> 16359552 | D113: =SUM(D2:D112) -> 6180192 | E113: =SUM(B113:D113) -> 26758624

Sheet Rail Ridership
A1: 2025 Totals (metro station codes) | D1: Merged Stations (in-gate xfer stations excluded) | J1: 2025 Boardings | K1: January | N1: February | Q1: March | T1: April | W1: May | Z1: June | AC1: July | AF1: August | AI1: September | AL1: October | AO1: November | AR1: December
A2: {=UNIQUE( TOCOL({ AR2:AR130; AO2:AO130; AL2:AL130; AI2:AI130; AF2:AF130; AC2:AC130; Z2:Z130; W2:W130; T2:T130; Q2:Q130; N2:N130; K2:K130 }, 1) )} -> 0001-Downtown Santa Monica Station | B2: =SUMPRODUCT( (--({ $K$2:$K$119; $N$2:$N$119; $Q$2:$Q$119; $T$2:$T$119; $W$2:$W$119; $Z$2:$Z$113; $AC$2:$AC$113; $AF$2:$AF$113; $AI$2:$AI$125; $AL$2:$AL$125; $AO$2:$AO$125; $AR$2:$AR$125 } = A2)), { $L$2:$L$119; $O$2:$O$119; $R$2:$R$119; $U$2:$U$119; $X$2:$X$119; $AA$2:$AA$113; $AD$2:$AD$113; $AG$2:$AG$113; $AJ$2:$AJ$125; $AM$2:$AM$125; $AP$2:$AP$125; $AS$2:$AS$125 } ) -> 1709706 | D2: 103rd Street / Watts Towers Station | E2: 602210 | K2: 0001-Downtown Santa Monica Station | L2: 115179 | N2: 0001-Downtown Santa Monica Station | O2: 118644 | Q2: 0001-Downtown Santa Monica Station | R2: 134837 | T2: 0001-Downtown Santa Monica Station | U2: 148074 | W2: 0001-Downtown Santa Monica Station | X2: 165385 | Z2: 0001-Downtown Santa Monica Station | AA2: 142359 | AC2: 0001-Downtown Santa Monica Station | AD2: 144034 | AF2: 0001-Downtown Santa Monica Station | AG2: 160340 | AI2: 0001-Downtown Santa Monica Station | AJ2: 152959 | AL2: 0001-Downtown Santa Monica Station | AM2: 152753 | AO2: 0001-Downtown Santa Monica Station | AP2: 136180 | AR2: 0001-Downtown Santa Monica Station | AS2: 138962
A3: 0002-17th Street / SMC Station | B3: =SUMPRODUCT( (--({ $K$2:$K$119; $N$2:$N$119; $Q$2:$Q$119; $T$2:$T$119; $W$2:$W$119; $Z$2:$Z$113; $AC$2:$AC$113; $AF$2:$AF$113; $AI$2:$AI$125; $AL$2:$AL$125; $AO$2:$AO$125; $AR$2:$AR$125 } = A3)), { $L$2:$L$119; $O$2:$O$119; $R$2:$R$119; $U$2:$U$119; $X$2:$X$119; $AA$2:$AA$113; $AD$2:$AD$113; $AG$2:$AG$113; $AJ$2:$AJ$125; $AM$2:$AM$125; $AP$2:$AP$125; $AS$2:$AS$125 } ) -> 502057 | D3: 17th Street / SMC Station | E3: 502057 | K3: 0002-17th Street / SMC Station | L3: 33997 | N3: 0002-17th Street / SMC Station | O3: 38088 | Q3: 0002-17th Street / SMC Station | R3: 44460 | T3: 0002-17th Street / SMC Station | U3: 44478 | W3: 0002-17th Street / SMC Station | X3: 46537 | Z3: 0002-17th Street / SMC Station | AA3: 37896 | AC3: 0002-17th Street / SMC Station | AD3: 38174 | AF3: 0002-17th Street / SMC Station | AG3: 37383 | AI3: 0002-17th Street / SMC Station | AJ3: 49702 | AL3: 0002-17th Street / SMC Station | AM3: 51383 | AO3: 0002-17th Street / SMC Station | AP3: 41009 | AR3: 0002-17th Street / SMC Station | AS3: 38950
A4: 0003-26th Street / Bergamot Station | B4: =SUMPRODUCT( (--({ $K$2:$K$119; $N$2:$N$119; $Q$2:$Q$119; $T$2:$T$119; $W$2:$W$119; $Z$2:$Z$113; $AC$2:$AC$113; $AF$2:$AF$113; $AI$2:$AI$125; $AL$2:$AL$125; $AO$2:$AO$125; $AR$2:$AR$125 } = A4)), { $L$2:$L$119; $O$2:$O$119; $R$2:$R$119; $U$2:$U$119; $X$2:$X$119; $AA$2:$AA$113; $AD$2:$AD$113; $AG$2:$AG$113; $AJ$2:$AJ$125; $AM$2:$AM$125; $AP$2:$AP$125; $AS$2:$AS$125 } ) -> 320761 | D4: 1st Street Station | E4: 104217 | K4: 0003-26th Street / Bergamot Station | L4: 22664 | N4: 0003-26th Street / Bergamot Station | O4: 24032 | Q4: 0003-26th Street / Bergamot Station | R4: 25914 | T4: 0003-26th Street / Bergamot Station | U4: 28352 | W4: 0003-26th Street / Bergamot Station | X4: 29338 | Z4: 0003-26th Street / Bergamot Station | AA4: 25866 | AC4: 0003-26th Street / Bergamot Station | AD4: 26117 | AF4: 0003-26th Street / Bergamot Station | AG4: 26638 | AI4: 0003-26th Street / Bergamot Station | AJ4: 29711 | AL4: 0003-26th Street / Bergamot Station | AM4: 30991 | AO4: 0003-26th Street / Bergamot Station | AP4: 25675 | AR4: 0003-26th Street / Bergamot Station | AS4: 25463
A5: 0004-Expo / Bundy Station | B5: =SUMPRODUCT( (--({ $K$2:$K$119; $N$2:$N$119; $Q$2:$Q$119; $T$2:$T$119; $W$2:$W$119; $Z$2:$Z$113; $AC$2:$AC$113; $AF$2:$AF$113; $AI$2:$AI$125; $AL$2:$AL$125; $AO$2:$AO$125; $AR$2:$AR$125 } = A5)), { $L$2:$L$119; $O$2:$O$119; $R$2:$R$119; $U$2:$U$119; $X$2:$X$119; $AA$2:$AA$113; $AD$2:$AD$113; $AG$2:$AG$113; $AJ$2:$AJ$125; $AM$2:$AM$125; $AP$2:$AP$125; $AS$2:$AS$125 } ) -> 469733 | D5: 26th Street / Bergamot Station | E5: 320761 | K5: 0004-Expo / Bundy Station | L5: 35503 | N5: 0004-Expo / Bundy Station | O5: 36868 | Q5: 0004-Expo / Bundy Station | R5: 39968 | T5: 0004-Expo / Bundy Station | U5: 41850 | W5: 0004-Expo / Bundy Station | X5: 44262 | Z5: 0004-Expo / Bundy Station | AA5: 35608 | AC5: 0004-Expo / Bundy Station | AD5: 34109 | AF5: 0004-Expo / Bundy Station | AG5: 37826 | AI5: 0004-Expo / Bundy Station | AJ5: 42304 | AL5: 0004-Expo / Bundy Station | AM5: 45866 | AO5: 0004-Expo / Bundy Station | AP5: 37639 | AR5: 0004-Expo / Bundy Station | AS5: 37930
A6: 0005-Expo / Sepulveda Station | B6: =SUMPRODUCT( (--({ $K$2:$K$119; $N$2:$N$119; $Q$2:$Q$119; $T$2:$T$119; $W$2:$W$119; $Z$2:$Z$113; $AC$2:$AC$113; $AF$2:$AF$113; $AI$2:$AI$125; $AL$2:$AL$125; $AO$2:$AO$125; $AR$2:$AR$125 } = A6)), { $L$2:$L$119; $O$2:$O$119; $R$2:$R$119; $U$2:$U$119; $X$2:$X$119; $AA$2:$AA$113; $AD$2:$AD$113; $AG$2:$AG$113; $AJ$2:$AJ$125; $AM$2:$AM$125; $AP$2:$AP$125; $AS$2:$AS$125 } ) -> 557665 | D6: 5th Street Station | E6: 118497 | K6: 0005-Expo / Sepulveda Station | L6: 41262 | N6: 0005-Expo / Sepulveda Station | O6: 41272 | Q6: 0005-Expo / Sepulveda Station | R6: 46327 | T6: 0005-Expo / Sepulveda Station | U6: 49934 | W6: 0005-Expo / Sepulveda Station | X6: 50684 | Z6: 0005-Expo / Sepulveda Station | AA6: 44430 | AC6: 0005-Expo / Sepulveda Station | AD6: 44990 | AF6: 0005-Expo / Sepulveda Station | AG6: 46821 | AI6: 0005-Expo / Sepulveda Station | AJ6: 49562 | AL6: 0005-Expo / Sepulveda Station | AM6: 52395 | AO6: 0005-Expo / Sepulveda Station | AP6: 45287 | AR6: 0005-Expo / Sepulveda Station | AS6: 44701
A7: 0006-Westwood / Rancho Park Station | B7: =SUMPRODUCT( (--({ $K$2:$K$119; $N$2:$N$119; $Q$2:$Q$119; $T$2:$T$119; $W$2:$W$119; $Z$2:$Z$113; $AC$2:$AC$113; $AF$2:$AF$113; $AI$2:$AI$125; $AL$2:$AL$125; $AO$2:$AO$125; $AR$2:$AR$125 } = A7)), { $L$2:$L$119; $O$2:$O$119; $R$2:$R$119; $U$2:$U$119; $X$2:$X$119; $AA$2:$AA$113; $AD$2:$AD$113; $AG$2:$AG$113; $AJ$2:$AJ$125; $AM$2:$AM$125; $AP$2:$AP$125; $AS$2:$AS$125 } ) -> 383654 | D7: Allen Station | E7: 243502 | K7: 0006-Westwood / Rancho Park Station | L7: 26985 | N7: 0006-Westwood / Rancho Park Station | O7: 29704 | Q7: 0006-Westwood / Rancho Park Station | R7: 30850 | T7: 0006-Westwood / Rancho Park Station | U7: 35548 | W7: 0006-Westwood / Rancho Park Station | X7: 36453 | Z7: 0006-Westwood / Rancho Park Station | AA7: 30185 | AC7: 0006-Westwood / Rancho Park Station | AD7: 30236 | AF7: 0006-Westwood / Rancho Park Station | AG7: 30181 | AI7: 0006-Westwood / Rancho Park Station | AJ7: 33166 | AL7: 0006-Westwood / Rancho Park Station | AM7: 38705 | AO7: 0006-Westwood / Rancho Park Station | AP7: 31808 | AR7: 0006-Westwood / Rancho Park Station | AS7: 29833
A8: 0007-Palms Station | B8: =SUMPRODUCT( (--({ $K$2:$K$119; $N$2:$N$119; $Q$2:$Q$119; $T$2:$T$119; $W$2:$W$119; $Z$2:$Z$113; $AC$2:$AC$113; $AF$2:$AF$113; $AI$2:$AI$125; $AL$2:$AL$125; $AO$2:$AO$125; $AR$2:$AR$125 } = A8)), { $L$2:$L$119; $O$2:$O$119; $R$2:$R$119; $U$2:$U$119; $X$2:$X$119; $AA$2:$AA$113; $AD$2:$AD$113; $AG$2:$AG$113; $AJ$2:$AJ$125; $AM$2:$AM$125; $AP$2:$AP$125; $AS$2:$AS$125 } ) -> 326195 | D8: Anaheim Street Station | E8: 593791 | K8: 0007-Palms Station | L8: 24111 | N8: 0007-Palms Station | O8: 24628 | Q8: 0007-Palms Station | R8: 27191 | T8: 0007-Palms Station | U8: 29762 | W8: 0007-Palms Station | X8: 28531 | Z8: 0007-Palms Station | AA8: 26156 | AC8: 0007-Palms Station | AD8: 25564 | AF8: 0007-Palms Station | AG8: 27654 | AI8: 0007-Palms Station | AJ8: 29166 | AL8: 0007-Palms Station | AM8: 31539 | AO8: 0007-Palms Station | AP8: 26687 | AR8: 0007-Palms Station | AS8: 25206
A9: 0008-Culver City Station | B9: =SUMPRODUCT( (--({ $K$2:$K$119; $N$2:$N$119; $Q$2:$Q$119; $T$2:$T$119; $W$2:$W$119; $Z$2:$Z$113; $AC$2:$AC$113; $AF$2:$AF$113; $AI$2:$AI$125; $AL$2:$AL$125; $AO$2:$AO$125; $AR$2:$AR$125 } = A9)), { $L$2:$L$119; $O$2:$O$119; $R$2:$R$119; $U$2:$U$119; $X$2:$X$119; $AA$2:$AA$113; $AD$2:$AD$113; $AG$2:$AG$113; $AJ$2:$AJ$125; $AM$2:$AM$125; $AP$2:$AP$125; $AS$2:$AS$125 } ) -> 677683 | D9: APU Station | E9: 417782 | K9: 0008-Culver City Station | L9: 50770 | N9: 0008-Culver City Station | O9: 51692 | Q9: 0008-Culver City Station | R9: 57008 | T9: 0008-Culver City Station | U9: 59262 | W9: 0008-Culver City Station | X9: 62248 | Z9: 0008-Culver City Station | AA9: 53942 | AC9: 0008-Culver City Station | AD9: 52229 | AF9: 0008-Culver City Station | AG9: 58766 | AI9: 0008-Culver City Station | AJ9: 60135 | AL9: 0008-Culver City Station | AM9: 64717 | AO9: 0008-Culver City Station | AP9: 53261 | AR9: 0008-Culver City Station | AS9: 53653
A10: 0009-La Cienega / Jefferson Station | B10: =SUMPRODUCT( (--({ $K$2:$K$119; $N$2:$N$119; $Q$2:$Q$119; $T$2:$T$119; $W$2:$W$119; $Z$2:$Z$113; $AC$2:$AC$113; $AF$2:$AF$113; $AI$2:$AI$125; $AL$2:$AL$125; $AO$2:$AO$125; $AR$2:$AR$125 } = A10)), { $L$2:$L$119; $O$2:$O$119; $R$2:$R$119; $U$2:$U$119; $X$2:$X$119; $AA$2:$AA$113; $AD$2:$AD$113; $AG$2:$AG$113; $AJ$2:$AJ$125; $AM$2:$AM$125; $AP$2:$AP$125; $AS$2:$AS$125 } ) -> 496577 | D10: Arcadia Station | E10: 299633 | K10: 0009-La Cienega / Jefferson Station | L10: 37840 | N10: 0009-La Cienega / Jefferson Station | O10: 37848 | Q10: 0009-La Cienega / Jefferson Station | R10: 40802 | T10: 0009-La Cienega / Jefferson Station | U10: 44268 | W10: 0009-La Cienega / Jefferson Station | X10: 44253 | Z10: 0009-La Cienega / Jefferson Station | AA10: 40217 | AC10: 0009-La Cienega / Jefferson Station | AD10: 39059 | AF10: 0009-La Cienega / Jefferson Station | AG10: 41231 | AI10: 0009-La Cienega / Jefferson Station | AJ10: 43490 | AL10: 0009-La Cienega / Jefferson Station | AM10: 46778 | AO10: 0009-La Cienega / Jefferson Station | AP10: 40436 | AR10: 0009-La Cienega / Jefferson Station | AS10: 40355
A11: 0010-Expo / La Brea / Ethel Bradley Station | B11: =SUMPRODUCT( (--({ $K$2:$K$119; $N$2:$N$119; $Q$2:$Q$119; $T$2:$T$119; $W$2:$W$119; $Z$2:$Z$113; $AC$2:$AC$113; $AF$2:$AF$113; $AI$2:$AI$125; $AL$2:$AL$125; $AO$2:$AO$125; $AR$2:$AR$125 } = A11)), { $L$2:$L$119; $O$2:$O$119; $R$2:$R$119; $U$2:$U$119; $X$2:$X$119; $AA$2:$AA$113; $AD$2:$AD$113; $AG$2:$AG$113; $AJ$2:$AJ$125; $AM$2:$AM$125; $AP$2:$AP$125; $AS$2:$AS$125 } ) -> 508800 | D11: Artesia Station | E11: 508580 | K11: 0010-Expo / La Brea / Ethel Bradley Station | L11: 39540 | N11: 0010-Expo / La Brea / Ethel Bradley Station | O11: 40384 | Q11: 0010-Expo / La Brea / Ethel Bradley Station | R11: 42735 | T11: 0010-Expo / La Brea / Ethel Bradley Station | U11: 45276 | W11: 0010-Expo / La Brea / Ethel Bradley Station | X11: 47397 | Z11: 0010-Expo / La Brea / Ethel Bradley Station | AA11: 40150 | AC11: 0010-Expo / La Brea / Ethel Bradley Station | AD11: 39795 | AF11: 0010-Expo / La Brea / Ethel Bradley Station | AG11: 42180 | AI11: 0010-Expo / La Brea / Ethel Bradley Station | AJ11: 44106 | AL11: 0010-Expo / La Brea / Ethel Bradley Station | AM11: 46186 | AO11: 0010-Expo / La Brea / Ethel Bradley Station | AP11: 40088 | AR11: 0010-Expo / La Brea / Ethel Bradley Station | AS11: 40963
A12: 0011-Farmdale Station | B12: =SUMPRODUCT( (--({ $K$2:$K$119; $N$2:$N$119; $Q$2:$Q$119; $T$2:$T$119; $W$2:$W$119; $Z$2:$Z$113; $AC$2:$AC$113; $AF$2:$AF$113; $AI$2:$AI$125; $AL$2:$AL$125; $AO$2:$AO$125; $AR$2:$AR$125 } = A12)), { $L$2:$L$119; $O$2:$O$119; $R$2:$R$119; $U$2:$U$119; $X$2:$X$119; $AA$2:$AA$113; $AD$2:$AD$113; $AG$2:$AG$113; $AJ$2:$AJ$125; $AM$2:$AM$125; $AP$2:$AP$125; $AS$2:$AS$125 } ) -> 285508 | D12: Atlantic Station | E12: 661730 | K12: 0011-Farmdale Station | L12: 22855 | N12: 0011-Farmdale Station | O12: 23052 | Q12: 0011-Farmdale Station | R12: 24364 | T12: 0011-Farmdale Station | U12: 24864 | W12: 0011-Farmdale Station | X12: 26765 | Z12: 0011-Farmdale Station | AA12: 21562 | AC12: 0011-Farmdale Station | AD12: 20533 | AF12: 0011-Farmdale Station | AG12: 23450 | AI12: 0011-Farmdale Station | AJ12: 25127 | AL12: 0011-Farmdale Station | AM12: 28273 | AO12: 0011-Farmdale Station | AP12: 22047 | AR12: 0011-Farmdale Station | AS12: 22616
A13: 0012-Expo / Crenshaw Station - E Line | B13: =SUMPRODUCT( (--({ $K$2:$K$119; $N$2:$N$119; $Q$2:$Q$119; $T$2:$T$119; $W$2:$W$119; $Z$2:$Z$113; $AC$2:$AC$113; $AF$2:$AF$113; $AI$2:$AI$125; $AL$2:$AL$125; $AO$2:$AO$125; $AR$2:$AR$125 } = A13)), { $L$2:$L$119; $O$2:$O$119; $R$2:$R$119; $U$2:$U$119; $X$2:$X$119; $AA$2:$AA$113; $AD$2:$AD$113; $AG$2:$AG$113; $AJ$2:$AJ$125; $AM$2:$AM$125; $AP$2:$AP$125; $AS$2:$AS$125 } ) -> 893584 | D13: Avalon Station | E13: 370024 | K13: 0012-Expo / Crenshaw Station - E Line | L13: 60996 | N13: 0012-Expo / Crenshaw Station - E Line | O13: 61768 | Q13: 0012-Expo / Crenshaw Station - E Line | R13: 64688 | T13: 0012-Expo / Crenshaw Station - E Line | U13: 67562 | W13: 0012-Expo / Crenshaw Station - E Line | X13: 71567 | Z13: 0012-Expo / Crenshaw Station - E Line | AA13: 75459 | AC13: 0012-Expo / Crenshaw Station - E Line | AD13: 76142 | AF13: 0012-Expo / Crenshaw Station - E Line | AG13: 84004 | AI13: 0012-Expo / Crenshaw Station - E Line | AJ13: 84091 | AL13: 0012-Expo / Crenshaw Station - E Line | AM13: 91351 | AO13: 0012-Expo / Crenshaw Station - E Line | AP13: 77777 | AR13: 0012-Expo / Crenshaw Station - E Line | AS13: 78179
A14: 0013-Expo / Western Station | B14: =SUMPRODUCT( (--({ $K$2:$K$119; $N$2:$N$119; $Q$2:$Q$119; $T$2:$T$119; $W$2:$W$119; $Z$2:$Z$113; $AC$2:$AC$113; $AF$2:$AF$113; $AI$2:$AI$125; $AL$2:$AL$125; $AO$2:$AO$125; $AR$2:$AR$125 } = A14)), { $L$2:$L$119; $O$2:$O$119; $R$2:$R$119; $U$2:$U$119; $X$2:$X$119; $AA$2:$AA$113; $AD$2:$AD$113; $AG$2:$AG$113; $AJ$2:$AJ$125; $AM$2:$AM$125; $AP$2:$AP$125; $AS$2:$AS$125 } ) -> 879577 | D14: Aviation Station | E14: 474364 | K14: 0013-Expo / Western Station | L14: 65419 | N14: 0013-Expo / Western Station | O14: 66496 | Q14: 0013-Expo / Western Station | R14: 73431 | T14: 0013-Expo / Western Station | U14: 77788 | W14: 0013-Expo / Western Station | X14: 82471 | Z14: 0013-Expo / Western Station | AA14: 67974 | AC14: 0013-Expo / Western Station | AD14: 69376 | AF14: 0013-Expo / Western Station | AG14: 73442 | AI14: 0013-Expo / Western Station | AJ14: 76959 | AL14: 0013-Expo / Western Station | AM14: 83070 | AO14: 0013-Expo / Western Station | AP14: 70193 | AR14: 0013-Expo / Western Station | AS14: 72958
... A105: 5001-Union Station - Metro Red & Purple Lines | B105: =SUMPRODUCT( (--({ $K$2:$K$119; $N$2:$N$119; $Q$2:$Q$119; $T$2:$T$119; $W$2:$W$119; $Z$2:$Z$113; $AC$2:$AC$113; $AF$2:$AF$113; $AI$2:$AI$125; $AL$2:$AL$125; $AO$2:$AO$125; $AR$2:$AR$125 } = A105)), { $L$2:$L$119; $O$2:$O$119; $R$2:$R$119; $U$2:$U$119; $X$2:$X$119; $AA$2:$AA$113; $AD$2:$AD$113; $AG$2:$AG$113; $AJ$2:$AJ$125; $AM$2:$AM$125; $AP$2:$AP$125; $AS$2:$AS$125 } ) -> 541524 | D105: Wilshire / Western Station | E105: 577178 | K105: 5006-Wilshire / Vermont Station | L105: 49266 | N105: 5006-Wilshire / Vermont Station | O105: 46256 | Q105: 5006-Wilshire / Vermont Station | R105: 53250 | T105: 5006-Wilshire / Vermont Station | U105: 53212 | W105: 5006-Wilshire / Vermont Station | X105: 53264 | Z105: 6005-Fairview Heights Station | AA105: 9820 | AC105: 6005-Fairview Heights Station | AD105: 8701 | AF105: 6005-Fairview Heights Station | AG105: 9306 | AI105: 5001-Union Station - Metro Red & Purple Lines | AJ105: 61855 | AL105: 5001-Union Station - Metro Red & Purple Lines | AM105: 54883 | AO105: 5001-Union Station - Metro Red & Purple Lines | AP105: 61684 | AR105: 5001-Union Station - Metro Red & Purple Lines | AS105: 59257
A106: 5002-Civic Center / Grand Park Station | B106: =SUMPRODUCT( (--({ $K$2:$K$119; $N$2:$N$119; $Q$2:$Q$119; $T$2:$T$119; $W$2:$W$119; $Z$2:$Z$113; $AC$2:$AC$113; $AF$2:$AF$113; $AI$2:$AI$125; $AL$2:$AL$125; $AO$2:$AO$125; $AR$2:$AR$125 } = A106)), { $L$2:$L$119; $O$2:$O$119; $R$2:$R$119; $U$2:$U$119; $X$2:$X$119; $AA$2:$AA$113; $AD$2:$AD$113; $AG$2:$AG$113; $AJ$2:$AJ$125; $AM$2:$AM$125; $AP$2:$AP$125; $AS$2:$AS$125 } ) -> 187693 | K106: 5007-Wilshire / Normandie Station | L106: 35515 | N106: 5007-Wilshire / Normandie Station | O106: 35936 | Q106: 5007-Wilshire / Normandie Station | R106: 38997 | T106: 5007-Wilshire / Normandie Station | U106: 40058 | W106: 5007-Wilshire / Normandie Station | X106: 39419 | Z106: 6006-Downtown Inglewood Station | AA106: 12410 | AC106: 6006-Downtown Inglewood Station | AD106: 14593 | AF106: 6006-Downtown Inglewood Station | AG106: 15771 | AI106: 5002-Civic Center / Grand Park Station | AJ106: 17872 | AL106: 5002-Civic Center / Grand Park Station | AM106: 20466 | AO106: 5002-Civic Center / Grand Park Station | AP106: 21182 | AR106: 5002-Civic Center / Grand Park Station | AS106: 17936
A107: 5003-Pershing Square Station | B107: =SUMPRODUCT( (--({ $K$2:$K$119; $N$2:$N$119; $Q$2:$Q$119; $T$2:$T$119; $W$2:$W$119; $Z$2:$Z$113; $AC$2:$AC$113; $AF$2:$AF$113; $AI$2:$AI$125; $AL$2:$AL$125; $AO$2:$AO$125; $AR$2:$AR$125 } = A107)), { $L$2:$L$119; $O$2:$O$119; $R$2:$R$119; $U$2:$U$119; $X$2:$X$119; $AA$2:$AA$113; $AD$2:$AD$113; $AG$2:$AG$113; $AJ$2:$AJ$125; $AM$2:$AM$125; $AP$2:$AP$125; $AS$2:$AS$125 } ) -> 356859 | K107: 5008-Wilshire / Western Station | L107: 66653 | N107: 5008-Wilshire / Western Station | O107: 60964 | Q107: 5008-Wilshire / Western Station | R107: 68728 | T107: 5008-Wilshire / Western Station | U107: 69546 | W107: 5008-Wilshire / Western Station | X107: 65664 | Z107: 6007-Westchester Station | AA107: 17754 | AC107: 6007-Westchester Station | AD107: 10862 | AF107: 6007-Westchester Station | AG107: 11846 | AI107: 5003-Pershing Square Station | AJ107: 36337 | AL107: 5003-Pershing Square Station | AM107: 38601 | AO107: 5003-Pershing Square Station | AP107: 35558 | AR107: 5003-Pershing Square Station | AS107: 34962
A108: 5004-7th Street / Metro Center Station - Metro Red & Purple Lines | B108: =SUMPRODUCT( (--({ $K$2:$K$119; $N$2:$N$119; $Q$2:$Q$119; $T$2:$T$119; $W$2:$W$119; $Z$2:$Z$113; $AC$2:$AC$113; $AF$2:$AF$113; $AI$2:$AI$125; $AL$2:$AL$125; $AO$2:$AO$125; $AR$2:$AR$125 } = A108)), { $L$2:$L$119; $O$2:$O$119; $R$2:$R$119; $U$2:$U$119; $X$2:$X$119; $AA$2:$AA$113; $AD$2:$AD$113; $AG$2:$AG$113; $AJ$2:$AJ$125; $AM$2:$AM$125; $AP$2:$AP$125; $AS$2:$AS$125 } ) -> 983361 | K108: 6001-Expo / Crenshaw Station - K Line | L108: 32583 | N108: 6001-Expo / Crenshaw Station - K Line | O108: 31764 | Q108: 6001-Expo / Crenshaw Station - K Line | R108: 34524 | T108: 6001-Expo / Crenshaw Station - K Line | U108: 33828 | W108: 6001-Expo / Crenshaw Station - K Line | X108: 36275 | Z108: 6008-AMC / LAX Station - K Line | AA108: 40191 | AC108: 6008-AMC / LAX Station - K Line | AD108: 32196 | AF108: 6008-AMC / LAX Station - K Line | AG108: 36005 | AI108: 5004-7th Street / Metro Center Station - Metro Red & Purple Lines | AJ108: 99873 | AL108: 5004-7th Street / Metro Center Station - Metro Red & Purple Lines | AM108: 112189 | AO108: 5004-7th Street / Metro Center Station - Metro Red & Purple Lines | AP108: 98785 | AR108: 5004-7th Street / Metro Center Station - Metro Red & Purple Lines | AS108: 103204
A109: 5005-Westlake / MacArthur Park Station | B109: =SUMPRODUCT( (--({ $K$2:$K$119; $N$2:$N$119; $Q$2:$Q$119; $T$2:$T$119; $W$2:$W$119; $Z$2:$Z$113; $AC$2:$AC$113; $AF$2:$AF$113; $AI$2:$AI$125; $AL$2:$AL$125; $AO$2:$AO$125; $AR$2:$AR$125 } = A109)), { $L$2:$L$119; $O$2:$O$119; $R$2:$R$119; $U$2:$U$119; $X$2:$X$119; $AA$2:$AA$113; $AD$2:$AD$113; $AG$2:$AG$113; $AJ$2:$AJ$125; $AM$2:$AM$125; $AP$2:$AP$125; $AS$2:$AS$125 } ) -> 455701 | K109: 6002-Martin Luther King Station | L109: 7354 | N109: 6002-Martin Luther King Station | O109: 7376 | Q109: 6002-Martin Luther King Station | R109: 6526 | T109: 6002-Martin Luther King Station | U109: 6732 | W109: 6002-Martin Luther King Station | X109: 7156 | Z109: 6009-Aviation Century Station - K Line | AA109: 29937 | AC109: 6009-Aviation Century Station - K Line | AD109: 28037 | AF109: 6009-Aviation Century Station - K Line | AG109: 26759 | AI109: 5005-Westlake / MacArthur Park Station | AJ109: 46076 | AL109: 5005-Westlake / MacArthur Park Station | AM109: 47800 | AO109: 5005-Westlake / MacArthur Park Station | AP109: 45987 | AR109: 5005-Westlake / MacArthur Park Station | AS109: 45089
A110: 5006-Wilshire / Vermont Station | B110: =SUMPRODUCT( (--({ $K$2:$K$119; $N$2:$N$119; $Q$2:$Q$119; $T$2:$T$119; $W$2:$W$119; $Z$2:$Z$113; $AC$2:$AC$113; $AF$2:$AF$113; $AI$2:$AI$125; $AL$2:$AL$125; $AO$2:$AO$125; $AR$2:$AR$125 } = A110)), { $L$2:$L$119; $O$2:$O$119; $R$2:$R$119; $U$2:$U$119; $X$2:$X$119; $AA$2:$AA$113; $AD$2:$AD$113; $AG$2:$AG$113; $AJ$2:$AJ$125; $AM$2:$AM$125; $AP$2:$AP$125; $AS$2:$AS$125 } ) -> 449427 | K110: 6003-Leimert Park Station | L110: 7009 | N110: 6003-Leimert Park Station | O110: 6888 | Q110: 6003-Leimert Park Station | R110: 6694 | T110: 6003-Leimert Park Station | U110: 6852 | W110: 6003-Leimert Park Station | X110: 6211 | Z110: 6010-Mariposa Station | AA110: 10795 | AC110: 6010-Mariposa Station | AD110: 9403 | AF110: 6010-Mariposa Station | AG110: 9199 | AI110: 5006-Wilshire / Vermont Station | AJ110: 47616 | AL110: 5006-Wilshire / Vermont Station | AM110: 50891 | AO110: 5006-Wilshire / Vermont Station | AP110: 46196 | AR110: 5006-Wilshire / Vermont Station | AS110: 49476
A111: 5007-Wilshire / Normandie Station | B111: =SUMPRODUCT( (--({ $K$2:$K$119; $N$2:$N$119; $Q$2:$Q$119; $T$2:$T$119; $W$2:$W$119; $Z$2:$Z$113; $AC$2:$AC$113; $AF$2:$AF$113; $AI$2:$AI$125; $AL$2:$AL$125; $AO$2:$AO$125; $AR$2:$AR$125 } = A111)), { $L$2:$L$119; $O$2:$O$119; $R$2:$R$119; $U$2:$U$119; $X$2:$X$119; $AA$2:$AA$113; $AD$2:$AD$113; $AG$2:$AG$113; $AJ$2:$AJ$125; $AM$2:$AM$125; $AP$2:$AP$125; $AS$2:$AS$125 } ) -> 339134 | K111: 6004-Hyde Park Station | L111: 10642 | N111: 6004-Hyde Park Station | O111: 9888 | Q111: 6004-Hyde Park Station | R111: 10684 | T111: 6004-Hyde Park Station | U111: 10932 | W111: 6004-Hyde Park Station | X111: 11428 | Z111: 6011-El Segundo Station | AA111: 8480 | AC111: 6011-El Segundo Station | AD111: 9214 | AF111: 6011-El Segundo Station | AG111: 8761 | AI111: 5007-Wilshire / Normandie Station | AJ111: 37791 | AL111: 5007-Wilshire / Normandie Station | AM111: 37619 | AO111: 5007-Wilshire / Normandie Station | AP111: 35834 | AR111: 5007-Wilshire / Normandie Station | AS111: 37965
